
Generating train split: 29143 examples [00:00, 40139.26 examples/s]
Generating train split: 6232 examples [00:00, 38385.71 examples/s]
Traceback (most recent call last):
  File "/media/data_dump/Ritwik/envs/genmqna/lib/python3.9/site-packages/huggingface_hub/utils/_errors.py", line 304, in hf_raise_for_status
    response.raise_for_status()
  File "/media/data_dump/Ritwik/envs/genmqna/lib/python3.9/site-packages/requests/models.py", line 1024, in raise_for_status
    raise HTTPError(http_error_msg, response=self)
requests.exceptions.HTTPError: 401 Client Error: Unauthorized for url: https://huggingface.co/google/gemma-2b-it/resolve/main/config.json
The above exception was the direct cause of the following exception:
Traceback (most recent call last):
  File "/media/data_dump/Ritwik/envs/genmqna/lib/python3.9/site-packages/transformers/utils/hub.py", line 402, in cached_file
    resolved_file = hf_hub_download(
  File "/media/data_dump/Ritwik/envs/genmqna/lib/python3.9/site-packages/huggingface_hub/utils/_validators.py", line 114, in _inner_fn
    return fn(*args, **kwargs)
  File "/media/data_dump/Ritwik/envs/genmqna/lib/python3.9/site-packages/huggingface_hub/file_download.py", line 1221, in hf_hub_download
    return _hf_hub_download_to_cache_dir(
  File "/media/data_dump/Ritwik/envs/genmqna/lib/python3.9/site-packages/huggingface_hub/file_download.py", line 1325, in _hf_hub_download_to_cache_dir
    _raise_on_head_call_error(head_call_error, force_download, local_files_only)
  File "/media/data_dump/Ritwik/envs/genmqna/lib/python3.9/site-packages/huggingface_hub/file_download.py", line 1823, in _raise_on_head_call_error
    raise head_call_error
  File "/media/data_dump/Ritwik/envs/genmqna/lib/python3.9/site-packages/huggingface_hub/file_download.py", line 1722, in _get_metadata_or_catch_error
    metadata = get_hf_file_metadata(url=url, proxies=proxies, timeout=etag_timeout, headers=headers)
  File "/media/data_dump/Ritwik/envs/genmqna/lib/python3.9/site-packages/huggingface_hub/utils/_validators.py", line 114, in _inner_fn
    return fn(*args, **kwargs)
  File "/media/data_dump/Ritwik/envs/genmqna/lib/python3.9/site-packages/huggingface_hub/file_download.py", line 1645, in get_hf_file_metadata
    r = _request_wrapper(
  File "/media/data_dump/Ritwik/envs/genmqna/lib/python3.9/site-packages/huggingface_hub/file_download.py", line 372, in _request_wrapper
    response = _request_wrapper(
  File "/media/data_dump/Ritwik/envs/genmqna/lib/python3.9/site-packages/huggingface_hub/file_download.py", line 396, in _request_wrapper
    hf_raise_for_status(response)
  File "/media/data_dump/Ritwik/envs/genmqna/lib/python3.9/site-packages/huggingface_hub/utils/_errors.py", line 321, in hf_raise_for_status
    raise GatedRepoError(message, response) from e
huggingface_hub.utils._errors.GatedRepoError: 401 Client Error. (Request ID: Root=1-67f4c0ca-01e9f95f5e2654c21711942b;fe3828dc-d5b7-480f-bffc-24e192ca257c)
Cannot access gated repo for url https://huggingface.co/google/gemma-2b-it/resolve/main/config.json.
Access to model google/gemma-2b-it is restricted. You must have access to it and be authenticated to access it. Please log in.
The above exception was the direct cause of the following exception:
Traceback (most recent call last):
  File "/media/data_dump/Ritwik/git/IndicGenQA/06_ft_LLMs.py", line 110, in <module>
    tokenizer = AutoTokenizer.from_pretrained(MODEL_NAME, trust_remote_code=True)
  File "/media/data_dump/Ritwik/envs/genmqna/lib/python3.9/site-packages/transformers/models/auto/tokenization_auto.py", line 854, in from_pretrained
    config = AutoConfig.from_pretrained(
  File "/media/data_dump/Ritwik/envs/genmqna/lib/python3.9/site-packages/transformers/models/auto/configuration_auto.py", line 976, in from_pretrained
    config_dict, unused_kwargs = PretrainedConfig.get_config_dict(pretrained_model_name_or_path, **kwargs)
  File "/media/data_dump/Ritwik/envs/genmqna/lib/python3.9/site-packages/transformers/configuration_utils.py", line 632, in get_config_dict
    config_dict, kwargs = cls._get_config_dict(pretrained_model_name_or_path, **kwargs)
  File "/media/data_dump/Ritwik/envs/genmqna/lib/python3.9/site-packages/transformers/configuration_utils.py", line 689, in _get_config_dict
    resolved_config_file = cached_file(
  File "/media/data_dump/Ritwik/envs/genmqna/lib/python3.9/site-packages/transformers/utils/hub.py", line 420, in cached_file
    raise EnvironmentError(
OSError: You are trying to access a gated repo.
Make sure to have access to it at https://huggingface.co/google/gemma-2b-it.
401 Client Error. (Request ID: Root=1-67f4c0ca-01e9f95f5e2654c21711942b;fe3828dc-d5b7-480f-bffc-24e192ca257c)
Cannot access gated repo for url https://huggingface.co/google/gemma-2b-it/resolve/main/config.json.
Access to model google/gemma-2b-it is restricted. You must have access to it and be authenticated to access it. Please log in.
Traceback (most recent call last):
  File "/media/data_dump/Ritwik/envs/genmqna/lib/python3.9/site-packages/huggingface_hub/utils/_errors.py", line 304, in hf_raise_for_status
    response.raise_for_status()
  File "/media/data_dump/Ritwik/envs/genmqna/lib/python3.9/site-packages/requests/models.py", line 1024, in raise_for_status
    raise HTTPError(http_error_msg, response=self)
requests.exceptions.HTTPError: 401 Client Error: Unauthorized for url: https://huggingface.co/google/gemma-2b-it/resolve/main/config.json
The above exception was the direct cause of the following exception:
Traceback (most recent call last):
  File "/media/data_dump/Ritwik/envs/genmqna/lib/python3.9/site-packages/transformers/utils/hub.py", line 402, in cached_file
    resolved_file = hf_hub_download(
  File "/media/data_dump/Ritwik/envs/genmqna/lib/python3.9/site-packages/huggingface_hub/utils/_validators.py", line 114, in _inner_fn
    return fn(*args, **kwargs)
  File "/media/data_dump/Ritwik/envs/genmqna/lib/python3.9/site-packages/huggingface_hub/file_download.py", line 1221, in hf_hub_download
    return _hf_hub_download_to_cache_dir(
  File "/media/data_dump/Ritwik/envs/genmqna/lib/python3.9/site-packages/huggingface_hub/file_download.py", line 1325, in _hf_hub_download_to_cache_dir
    _raise_on_head_call_error(head_call_error, force_download, local_files_only)
  File "/media/data_dump/Ritwik/envs/genmqna/lib/python3.9/site-packages/huggingface_hub/file_download.py", line 1823, in _raise_on_head_call_error
    raise head_call_error
  File "/media/data_dump/Ritwik/envs/genmqna/lib/python3.9/site-packages/huggingface_hub/file_download.py", line 1722, in _get_metadata_or_catch_error
    metadata = get_hf_file_metadata(url=url, proxies=proxies, timeout=etag_timeout, headers=headers)
  File "/media/data_dump/Ritwik/envs/genmqna/lib/python3.9/site-packages/huggingface_hub/utils/_validators.py", line 114, in _inner_fn
    return fn(*args, **kwargs)
  File "/media/data_dump/Ritwik/envs/genmqna/lib/python3.9/site-packages/huggingface_hub/file_download.py", line 1645, in get_hf_file_metadata
    r = _request_wrapper(
  File "/media/data_dump/Ritwik/envs/genmqna/lib/python3.9/site-packages/huggingface_hub/file_download.py", line 372, in _request_wrapper
    response = _request_wrapper(
  File "/media/data_dump/Ritwik/envs/genmqna/lib/python3.9/site-packages/huggingface_hub/file_download.py", line 396, in _request_wrapper
    hf_raise_for_status(response)
  File "/media/data_dump/Ritwik/envs/genmqna/lib/python3.9/site-packages/huggingface_hub/utils/_errors.py", line 321, in hf_raise_for_status
    raise GatedRepoError(message, response) from e
huggingface_hub.utils._errors.GatedRepoError: 401 Client Error. (Request ID: Root=1-67f4c0ca-01e9f95f5e2654c21711942b;fe3828dc-d5b7-480f-bffc-24e192ca257c)
Cannot access gated repo for url https://huggingface.co/google/gemma-2b-it/resolve/main/config.json.
Access to model google/gemma-2b-it is restricted. You must have access to it and be authenticated to access it. Please log in.
The above exception was the direct cause of the following exception:
Traceback (most recent call last):
  File "/media/data_dump/Ritwik/git/IndicGenQA/06_ft_LLMs.py", line 110, in <module>
    tokenizer = AutoTokenizer.from_pretrained(MODEL_NAME, trust_remote_code=True)
  File "/media/data_dump/Ritwik/envs/genmqna/lib/python3.9/site-packages/transformers/models/auto/tokenization_auto.py", line 854, in from_pretrained
    config = AutoConfig.from_pretrained(
  File "/media/data_dump/Ritwik/envs/genmqna/lib/python3.9/site-packages/transformers/models/auto/configuration_auto.py", line 976, in from_pretrained
    config_dict, unused_kwargs = PretrainedConfig.get_config_dict(pretrained_model_name_or_path, **kwargs)
  File "/media/data_dump/Ritwik/envs/genmqna/lib/python3.9/site-packages/transformers/configuration_utils.py", line 632, in get_config_dict
    config_dict, kwargs = cls._get_config_dict(pretrained_model_name_or_path, **kwargs)
  File "/media/data_dump/Ritwik/envs/genmqna/lib/python3.9/site-packages/transformers/configuration_utils.py", line 689, in _get_config_dict
    resolved_config_file = cached_file(
  File "/media/data_dump/Ritwik/envs/genmqna/lib/python3.9/site-packages/transformers/utils/hub.py", line 420, in cached_file
    raise EnvironmentError(
OSError: You are trying to access a gated repo.
Make sure to have access to it at https://huggingface.co/google/gemma-2b-it.
401 Client Error. (Request ID: Root=1-67f4c0ca-01e9f95f5e2654c21711942b;fe3828dc-d5b7-480f-bffc-24e192ca257c)
Cannot access gated repo for url https://huggingface.co/google/gemma-2b-it/resolve/main/config.json.
Access to model google/gemma-2b-it is restricted. You must have access to it and be authenticated to access it. Please log in.